Workbook

Sheet Summary
A1: Smart Irrigation Advisory - Statistical Report
A2: Dataset: Crop_recommendationV2_final.csv | all numbers below link to the analysis sheets
A4: Dataset overview
A5: Records | B5: =ROWS(Data!$A$2:$A$2201) -> 2200
A6: Validation verdict | B6: =Validation!B35 -> PASS - no missing, duplicate, out-of-range or inconsistent entries found
A8: Key statistics
A9: Variable | B9: Mean | C9: Median | D9: Std dev | E9: Min | F9: Max | G9: Q1 | H9: Q3
A10: Temperature (°C) | B10: =Descriptive!B6 -> 25.616244 | C10: =Descriptive!B7 -> 25.598693 | D10: =Descriptive!B12 -> 5.0637486 | E10: =Descriptive!B14 -> 8.8256747 | F10: =Descriptive!B15 -> 43.675493 | G10: =Descriptive!B17 -> 22.769375 | H10: =Descriptive!B18 -> 28.561654
A11: Rainfall (mm) | B11: =Descriptive!C6 -> 103.46366 | C11: =Descriptive!C7 -> 94.867624 | D11: =Descriptive!C12 -> 54.958389 | E11: =Descriptive!C14 -> 20.211267 | F11: =Descriptive!C15 -> 298.56012 | G11: =Descriptive!C17 -> 64.551686 | H11: =Descriptive!C18 -> 124.26751
A12: Soil moisture (%) | B12: =Descriptive!D6 -> 20.151388 | C12: =Descriptive!D7 -> 20.088481 | D12: =Descriptive!D12 -> 5.7937198 | E12: =Descriptive!D14 -> 10.02426 | F12: =Descriptive!D15 -> 29.99786 | G12: =Descriptive!D17 -> 15.179949 | H12: =Descriptive!D18 -> 25.255146
A14: Correlations
A15: Pair | B15: r | C15: Strength | D15: p-value
A16: =Correlation!A11 -> Temperature vs Rainfall | B16: =Correlation!B11 -> -0.030083781 | C16: =Correlation!G11 -> Negligible | D16: =Correlation!F11 -> 0.15837094
A17: =Correlation!A12 -> Temperature vs Soil moisture | B17: =Correlation!B12 -> -0.009842308 | C17: =Correlation!G12 -> Negligible | D17: =Correlation!F12 -> 0.64451597
A18: =Correlation!A13 -> Rainfall vs Soil moisture | B18: =Correlation!B13 -> -0.048593299 | C18: =Correlation!G13 -> Negligible | D18: =Correlation!F13 -> 0.022650491
A20: Outliers (IQR)
A21: Variable | B21: Low | C21: High | D21: Total | E21: % of records
A22: Temperature (°C) | B22: =Outliers!G6 -> 38 | C22: =Outliers!H6 -> 48 | D22: =Outliers!I6 -> 86 | E22: =Outliers!J6 -> 0.039090909
A23: Rainfall (mm) | B23: =Outliers!G7 -> 0 | C23: =Outliers!H7 -> 100 | D23: =Outliers!I7 -> 100 | E23: =Outliers!J7 -> 0.045454545
A24: Soil moisture (%) | B24: =Outliers!G8 -> 0 | C24: =Outliers!H8 -> 0 | D24: =Outliers!I8 -> 0 | E24: =Outliers!J8 -> 0
A26: Written findings
A27: 1. Data quality: see the verdict above. No missing values, duplicates or out-of-range entries; categories and irrigation status match the thresholds on the Assumptions sheet.
A28: 2. Soil moisture is spread almost evenly between 10% and 30% (mean 20.2%, skew -0.02); temperature is roughly symmetric (mean 25.6 °C); rainfall is right-skewed (mean 103 mm vs median 95 mm).
A29: 3. Temperature, rainfall and soil moisture are essentially uncorrelated (all |r| < 0.05). The rainfall-moisture link is detectable at n = 2,200 (p = 0.023) but explains about 0.2% of variation.
A30: 4. Cross-tab: Low rainfall -> 39% "Irrigate Now", 0% "No Irrigation"; High rainfall -> 0% "Irrigate Now", 22% "No Irrigation". Chi-square p < 0.001 (Cramer's V = 0.23). Temperature category is detectable (p = 0.001) but negligible in size (V = 0.06).
A31: 5. Outliers: temperature 86 (48 hot, 38 cold), rainfall 100 (all high), soil moisture 0. They are plausible extremes, so they were kept.
A32: 6. Group averages: moisture 14.0% / 20.7% / 27.6% and rainfall 65 / 108 / 144 mm for Irrigate Now / Monitor / No Irrigation.
A34: Engineering insights
A35: Irrigation Status is calculated from soil moisture and rainfall (Irrigate Now: moisture < 18% and rainfall < 100 mm; No Irrigation: moisture >= 25% and rainfall >= 100 mm; otherwise Monitor). All 2,200 rows follow this rule, so the link between status and those two variables is built in, not discovered.
A36: Between the two extreme statuses, soil moisture differs by 2.4 SD and rainfall by 1.4 SD, so moisture is the variable most closely associated with irrigation need, with rainfall second. Temperature is not in the rule and differs by only -0.26 SD.
A37: These are associations in a rule-labelled dataset. They do not show that moisture or rainfall cause irrigation need in a real field, and correlation alone would not justify that claim.
A39: Points to resolve before submission
... A42: The decision rules are fixed thresholds (rule-based), not machine learning; describe them as a rule-based advisory system.

Sheet Data
A1: temperature | B1: rainfall | C1: soil_moisture | D1: Temperature Category | E1: Rainfall Category | F1: Water Requirement | G1: Irrigation Status | H1: AI Recommendation | I1: Temp Outlier (IQR) | J1: Rain Outlier (IQR) | K1: Moisture Outlier (IQR) | L1: Record Key (helper) | M1: Duplicate Flag | N1: Rule-Expected Status | O1: Status Matches Rule
A2: 20.879744 | B2: 202.93554 | C2: 29.446064 | D2: Moderate | E2: High | F2: Low | G2: No Irrigation Needed | H2: Do not irrigate now; soil moisture and rainfall are adequate. | I2: =IF(A2<Outliers!$E$6,"Low",IF(A2>Outliers!$F$6,"High","")) | J2: =IF(B2<Outliers!$E$7,"Low",IF(B2>Outliers!$F$7,"High","")) | K2: =IF(C2<Outliers!$E$8,"Low",IF(C2>Outliers!$F$8,"High","")) | L2: =A2&";"&B2&";"&C2 -> 20.87974371;202.9355362;29.4460639248291 | M2: =IF(COUNTIF($L$2:$L$2201,L2)>1,1,0) -> 0 | N2: =IF(AND(C2<Assumptions!$B$9,B2<Assumptions!$B$10),"Irrigate Now",IF(AND(C2>=Assumptions!$B$11,B2>=Assumptions!$B$12),"No Irrigation Needed","Monitor")) -> No Irrigation Needed | O2: =IF(N2=G2,1,0) -> 1
A3: 21.770462 | B3: 226.65554 | C3: 12.851183 | D3: Moderate | E3: High | F3: Medium | G3: Monitor | H3: Delay irrigation and monitor soil moisture after rainfall. | I3: =IF(A3<Outliers!$E$6,"Low",IF(A3>Outliers!$F$6,"High","")) | J3: =IF(B3<Outliers!$E$7,"Low",IF(B3>Outliers!$F$7,"High","")) -> High | K3: =IF(C3<Outliers!$E$8,"Low",IF(C3>Outliers!$F$8,"High","")) | L3: =A3&";"&B3&";"&C3 -> 21.77046169;226.6555374;12.851182636937 | M3: =IF(COUNTIF($L$2:$L$2201,L3)>1,1,0) -> 0 | N3: =IF(AND(C3<Assumptions!$B$9,B3<Assumptions!$B$10),"Irrigate Now",IF(AND(C3>=Assumptions!$B$11,B3>=Assumptions!$B$12),"No Irrigation Needed","Monitor")) -> Monitor | O3: =IF(N3=G3,1,0) -> 1
A4: 23.004459 | B4: 263.96425 | C4: 29.363913 | D4: Moderate | E4: High | F4: Low | G4: No Irrigation Needed | H4: Do not irrigate now; soil moisture and rainfall are adequate. | I4: =IF(A4<Outliers!$E$6,"Low",IF(A4>Outliers!$F$6,"High","")) | J4: =IF(B4<Outliers!$E$7,"Low",IF(B4>Outliers!$F$7,"High","")) -> High | K4: =IF(C4<Outliers!$E$8,"Low",IF(C4>Outliers!$F$8,"High","")) | L4: =A4&";"&B4&";"&C4 -> 23.00445915;263.9642476;29.3639128910548 | M4: =IF(COUNTIF($L$2:$L$2201,L4)>1,1,0) -> 0 | N4: =IF(AND(C4<Assumptions!$B$9,B4<Assumptions!$B$10),"Irrigate Now",IF(AND(C4>=Assumptions!$B$11,B4>=Assumptions!$B$12),"No Irrigation Needed","Monitor")) -> No Irrigation Needed | O4: =IF(N4=G4,1,0) -> 1
A5: 26.491096 | B5: 242.86403 | C5: 26.207732 | D5: Moderate | E5: High | F5: Low | G5: No Irrigation Needed | H5: Do not irrigate now; soil moisture and rainfall are adequate. | I5: =IF(A5<Outliers!$E$6,"Low",IF(A5>Outliers!$F$6,"High","")) | J5: =IF(B5<Outliers!$E$7,"Low",IF(B5>Outliers!$F$7,"High","")) -> High | K5: =IF(C5<Outliers!$E$8,"Low",IF(C5>Outliers!$F$8,"High","")) | L5: =A5&";"&B5&";"&C5 -> 26.49109635;242.8640342;26.2077323929988 | M5: =IF(COUNTIF($L$2:$L$2201,L5)>1,1,0) -> 0 | N5: =IF(AND(C5<Assumptions!$B$9,B5<Assumptions!$B$10),"Irrigate Now",IF(AND(C5>=Assumptions!$B$11,B5>=Assumptions!$B$12),"No Irrigation Needed","Monitor")) -> No Irrigation Needed | O5: =IF(N5=G5,1,0) -> 1
A6: 20.130175 | B6: 262.71734 | C6: 28.236236 | D6: Moderate | E6: High | F6: Low | G6: No Irrigation Needed | H6: Do not irrigate now; soil moisture and rainfall are adequate. | I6: =IF(A6<Outliers!$E$6,"Low",IF(A6>Outliers!$F$6,"High","")) | J6: =IF(B6<Outliers!$E$7,"Low",IF(B6>Outliers!$F$7,"High","")) -> High | K6: =IF(C6<Outliers!$E$8,"Low",IF(C6>Outliers!$F$8,"High","")) | L6: =A6&";"&B6&";"&C6 -> 20.13017482;262.7173405;28.2362361358356 | M6: =IF(COUNTIF($L$2:$L$2201,L6)>1,1,0) -> 0 | N6: =IF(AND(C6<Assumptions!$B$9,B6<Assumptions!$B$10),"Irrigate Now",IF(AND(C6>=Assumptions!$B$11,B6>=Assumptions!$B$12),"No Irrigation Needed","Monitor")) -> No Irrigation Needed | O6: =IF(N6=G6,1,0) -> 1
A7: 23.058049 | B7: 251.055 | C7: 23.613115 | D7: Moderate | E7: High | F7: Low | G7: Monitor | H7: Delay irrigation and monitor soil moisture after rainfall. | I7: =IF(A7<Outliers!$E$6,"Low",IF(A7>Outliers!$F$6,"High","")) | J7: =IF(B7<Outliers!$E$7,"Low",IF(B7>Outliers!$F$7,"High","")) -> High | K7: =IF(C7<Outliers!$E$8,"Low",IF(C7>Outliers!$F$8,"High","")) | L7: =A7&";"&B7&";"&C7 -> 23.05804872;251.0549998;23.6131151961422 | M7: =IF(COUNTIF($L$2:$L$2201,L7)>1,1,0) -> 0 | N7: =IF(AND(C7<Assumptions!$B$9,B7<Assumptions!$B$10),"Irrigate Now",IF(AND(C7>=Assumptions!$B$11,B7>=Assumptions!$B$12),"No Irrigation Needed","Monitor")) -> Monitor | O7: =IF(N7=G7,1,0) -> 1
A8: 22.708838 | B8: 271.32486 | C8: 15.333693 | D8: Moderate | E8: High | F8: Medium | G8: Monitor | H8: Delay irrigation and monitor soil moisture after rainfall. | I8: =IF(A8<Outliers!$E$6,"Low",IF(A8>Outliers!$F$6,"High","")) | J8: =IF(B8<Outliers!$E$7,"Low",IF(B8>Outliers!$F$7,"High","")) -> High | K8: =IF(C8<Outliers!$E$8,"Low",IF(C8>Outliers!$F$8,"High","")) | L8: =A8&";"&B8&";"&C8 -> 22.70883798;271.3248604;15.333693105309 | M8: =IF(COUNTIF($L$2:$L$2201,L8)>1,1,0) -> 0 | N8: =IF(AND(C8<Assumptions!$B$9,B8<Assumptions!$B$10),"Irrigate Now",IF(AND(C8>=Assumptions!$B$11,B8>=Assumptions!$B$12),"No Irrigation Needed","Monitor")) -> Monitor | O8: =IF(N8=G8,1,0) -> 1
A9: 20.277744 | B9: 241.97419 | C9: 20.83564 | D9: Moderate | E9: High | F9: Low | G9: Monitor | H9: Delay irrigation and monitor soil moisture after rainfall. | I9: =IF(A9<Outliers!$E$6,"Low",IF(A9>Outliers!$F$6,"High","")) | J9: =IF(B9<Outliers!$E$7,"Low",IF(B9>Outliers!$F$7,"High","")) -> High | K9: =IF(C9<Outliers!$E$8,"Low",IF(C9>Outliers!$F$8,"High","")) | L9: =A9&";"&B9&";"&C9 -> 20.27774362;241.9741949;20.8356404825321 | M9: =IF(COUNTIF($L$2:$L$2201,L9)>1,1,0) -> 0 | N9: =IF(AND(C9<Assumptions!$B$9,B9<Assumptions!$B$10),"Irrigate Now",IF(AND(C9>=Assumptions!$B$11,B9>=Assumptions!$B$12),"No Irrigation Needed","Monitor")) -> Monitor | O9: =IF(N9=G9,1,0) -> 1
A10: 24.515881 | B10: 230.44624 | C10: 26.640656 | D10: Moderate | E10: High | F10: Low | G10: No Irrigation Needed | H10: Do not irrigate now; soil moisture and rainfall are adequate. | I10: =IF(A10<Outliers!$E$6,"Low",IF(A10>Outliers!$F$6,"High","")) | J10: =IF(B10<Outliers!$E$7,"Low",IF(B10>Outliers!$F$7,"High","")) -> High | K10: =IF(C10<Outliers!$E$8,"Low",IF(C10>Outliers!$F$8,"High","")) | L10: =A10&";"&B10&";"&C10 -> 24.51588066;230.4462359;26.6406557684007 | M10: =IF(COUNTIF($L$2:$L$2201,L10)>1,1,0) -> 0 | N10: =IF(AND(C10<Assumptions!$B$9,B10<Assumptions!$B$10),"Irrigate Now",IF(AND(C10>=Assumptions!$B$11,B10>=Assumptions!$B$12),"No Irrigation Needed","Monitor")) -> No Irrigation Needed | O10: =IF(N10=G10,1,0) -> 1
A11: 23.223974 | B11: 221.2092 | C11: 24.368853 | D11: Moderate | E11: High | F11: Low | G11: Monitor | H11: Delay irrigation and monitor soil moisture after rainfall. | I11: =IF(A11<Outliers!$E$6,"Low",IF(A11>Outliers!$F$6,"High","")) | J11: =IF(B11<Outliers!$E$7,"Low",IF(B11>Outliers!$F$7,"High","")) -> High | K11: =IF(C11<Outliers!$E$8,"Low",IF(C11>Outliers!$F$8,"High","")) | L11: =A11&";"&B11&";"&C11 -> 23.22397386;221.2091958;24.3688529174328 | M11: =IF(COUNTIF($L$2:$L$2201,L11)>1,1,0) -> 0 | N11: =IF(AND(C11<Assumptions!$B$9,B11<Assumptions!$B$10),"Irrigate Now",IF(AND(C11>=Assumptions!$B$11,B11>=Assumptions!$B$12),"No Irrigation Needed","Monitor")) -> Monitor | O11: =IF(N11=G11,1,0) -> 1
A12: 26.527235 | B12: 264.61487 | C12: 20.459146 | D12: Moderate | E12: High | F12: Low | G12: Monitor | H12: Delay irrigation and monitor soil moisture after rainfall. | I12: =IF(A12<Outliers!$E$6,"Low",IF(A12>Outliers!$F$6,"High","")) | J12: =IF(B12<Outliers!$E$7,"Low",IF(B12>Outliers!$F$7,"High","")) -> High | K12: =IF(C12<Outliers!$E$8,"Low",IF(C12>Outliers!$F$8,"High","")) | L12: =A12&";"&B12&";"&C12 -> 26.52723513;264.6148697;20.4591457410829 | M12: =IF(COUNTIF($L$2:$L$2201,L12)>1,1,0) -> 0 | N12: =IF(AND(C12<Assumptions!$B$9,B12<Assumptions!$B$10),"Irrigate Now",IF(AND(C12>=Assumptions!$B$11,B12>=Assumptions!$B$12),"No Irrigation Needed","Monitor")) -> Monitor | O12: =IF(N12=G12,1,0) -> 1
A13: 23.978982 | B13: 250.08323 | C13: 15.4046 | D13: Moderate | E13: High | F13: Medium | G13: Monitor | H13: Delay irrigation and monitor soil moisture after rainfall. | I13: =IF(A13<Outliers!$E$6,"Low",IF(A13>Outliers!$F$6,"High","")) | J13: =IF(B13<Outliers!$E$7,"Low",IF(B13>Outliers!$F$7,"High","")) -> High | K13: =IF(C13<Outliers!$E$8,"Low",IF(C13>Outliers!$F$8,"High","")) | L13: =A13&";"&B13&";"&C13 -> 23.97898217;250.0832336;15.4046004460179 | M13: =IF(COUNTIF($L$2:$L$2201,L13)>1,1,0) -> 0 | N13: =IF(AND(C13<Assumptions!$B$9,B13<Assumptions!$B$10),"Irrigate Now",IF(AND(C13>=Assumptions!$B$11,B13>=Assumptions!$B$12),"No Irrigation Needed","Monitor")) -> Monitor | O13: =IF(N13=G13,1,0) -> 1
... A2201: 23.603016 | B2201: 140.93704 | C2201: 23.911728 | D2201: Moderate | E2201: Moderate | F2201: Low | G2201: Monitor | H2201: Monitor soil moisture and irrigate if it drops further. | I2201: =IF(A2201<Outliers!$E$6,"Low",IF(A2201>Outliers!$F$6,"High","")) | J2201: =IF(B2201<Outliers!$E$7,"Low",IF(B2201>Outliers!$F$7,"High","")) | K2201: =IF(C2201<Outliers!$E$8,"Low",IF(C2201>Outliers!$F$8,"High","")) | L2201: =A2201&";"&B2201&";"&C2201 -> 23.60301571;140.9370415;23.9117275784086 | M2201: =IF(COUNTIF($L$2:$L$2201,L2201)>1,1,0) -> 0 | N2201: =IF(AND(C2201<Assumptions!$B$9,B2201<Assumptions!$B$10),"Irrigate Now",IF(AND(C2201>=Assumptions!$B$11,B2201>=Assumptions!$B$12),"No Irrigation Needed","Monitor")) -> Monitor | O2201: =IF(N2201=G2201,1,0) -> 1

Sheet Assumptions
A1: Assumptions & Parameters
A2: Blue cells are inputs. Every threshold below was INFERRED from the data (see notes) - confirm with the team. Change a value and the checks update.
A4: Parameter | B4: Value | C4: How it was derived
A5: Temperature: "Cool" if below (°C) | B5: 20 | C5: Cool max = 19.97, Moderate min = 20.00 in the data
A6: Temperature: "Hot" if at/above (°C) | B6: 30 | C6: Moderate max = 29.997, Hot min = 30.02 in the data
A7: Rainfall: "Low" if below (mm) | B7: 50 | C7: Low max = 49.94, Moderate min = 50.02 in the data
A8: Rainfall: "High" if at/above (mm) | B8: 150 | C8: Moderate max = 149.91, High min = 150.05 in the data
A9: Irrigate Now: soil moisture below (%) | B9: 18 | C9: Irrigate Now moisture max = 17.99 in the data
A10: Irrigate Now: rainfall below (mm) | B10: 100 | C10: Irrigate Now rainfall max = 99.93 in the data
A11: No Irrigation: soil moisture at/above (%) | B11: 25 | C11: No-Irrigation moisture min = 25.01 in the data
A12: No Irrigation: rainfall at/above (mm) | B12: 100 | C12: No-Irrigation rainfall min = 100.12 in the data
A13: All other rows = "Monitor". These rules reproduce Irrigation Status for 100% of the 2,200 rows (see Validation).
A14: Plausibility range (for validation) | B14: Value | C14: Note
A15: Temperature minimum (°C) | B15: -10 | C15: Assumed physical limit for an agricultural region
A16: Temperature maximum (°C) | B16: 60 | C16: Assumed physical limit
A17: Soil moisture minimum (%) | B17: 0 | C17: A percentage cannot be below 0
A18: Soil moisture maximum (%) | B18: 100 | C18: A percentage cannot exceed 100
A19: Rainfall minimum (mm) | B19: 0 | C19: Rainfall cannot be negative
A20: Rainfall maximum (mm) | B20: 1000 | C20: Assumed upper limit for the rainfall measure used

Sheet Validation
A1: Data Validation
A2: Checks run BEFORE the statistics. Thresholds come from the Assumptions sheet.
A3: 1. Completeness (missing / non-numeric)
A4: Column | B4: Expected rows | C4: Non-empty | D4: Missing | E4: Non-numeric | F4: Status
A5: temperature | B5: =ROWS(Data!$A$2:$A$2201) -> 2200 | C5: =COUNTA(Data!$A$2:$A$2201) -> 2200 | D5: =B5-C5 -> 0 | E5: =C5-COUNT(Data!$A$2:$A$2201) -> 0 | F5: =IF(AND(D5=0,N(E5)=0),"OK","CHECK") -> OK
A6: rainfall | B6: =ROWS(Data!$B$2:$B$2201) -> 2200 | C6: =COUNTA(Data!$B$2:$B$2201) -> 2200 | D6: =B6-C6 -> 0 | E6: =C6-COUNT(Data!$B$2:$B$2201) -> 0 | F6: =IF(AND(D6=0,N(E6)=0),"OK","CHECK") -> OK
A7: soil_moisture | B7: =ROWS(Data!$C$2:$C$2201) -> 2200 | C7: =COUNTA(Data!$C$2:$C$2201) -> 2200 | D7: =B7-C7 -> 0 | E7: =C7-COUNT(Data!$C$2:$C$2201) -> 0 | F7: =IF(AND(D7=0,N(E7)=0),"OK","CHECK") -> OK
A8: Temperature Category | B8: =ROWS(Data!$D$2:$D$2201) -> 2200 | C8: =COUNTA(Data!$D$2:$D$2201) -> 2200 | D8: =B8-C8 -> 0 | E8: n/a | F8: =IF(AND(D8=0,N(E8)=0),"OK","CHECK") -> OK
A9: Rainfall Category | B9: =ROWS(Data!$E$2:$E$2201) -> 2200 | C9: =COUNTA(Data!$E$2:$E$2201) -> 2200 | D9: =B9-C9 -> 0 | E9: n/a | F9: =IF(AND(D9=0,N(E9)=0),"OK","CHECK") -> OK
A10: Water Requirement | B10: =ROWS(Data!$F$2:$F$2201) -> 2200 | C10: =COUNTA(Data!$F$2:$F$2201) -> 2200 | D10: =B10-C10 -> 0 | E10: n/a | F10: =IF(AND(D10=0,N(E10)=0),"OK","CHECK") -> OK
A11: Irrigation Status | B11: =ROWS(Data!$G$2:$G$2201) -> 2200 | C11: =COUNTA(Data!$G$2:$G$2201) -> 2200 | D11: =B11-C11 -> 0 | E11: n/a | F11: =IF(AND(D11=0,N(E11)=0),"OK","CHECK") -> OK
A12: AI Recommendation | B12: =ROWS(Data!$H$2:$H$2201) -> 2200 | C12: =COUNTA(Data!$H$2:$H$2201) -> 2200 | D12: =B12-C12 -> 0 | E12: n/a | F12: =IF(AND(D12=0,N(E12)=0),"OK","CHECK") -> OK
A14: 2. Duplicate records
A15: Check | B15: Count | C15: Status
A16: Duplicate (temperature, rainfall, soil_moisture) rows | B16: =SUM(Data!$M$2:$M$2201) -> 0 | C16: =IF(B16=0,"OK","CHECK") -> OK
A18: 3. Range / plausibility
A19: Variable | B19: Plausible min | C19: Plausible max | D19: Below min | E19: Above max | F19: Status
A20: temperature (°C) | B20: =Assumptions!B15 -> -10 | C20: =Assumptions!B16 -> 60 | D20: =COUNTIF(Data!$A$2:$A$2201,"<"&B20) -> 0 | E20: =COUNTIF(Data!$A$2:$A$2201,">"&C20) -> 0 | F20: =IF(D20+E20=0,"OK","CHECK") -> OK
A21: rainfall (mm) | B21: =Assumptions!B19 -> 0 | C21: =Assumptions!B20 -> 1000 | D21: =COUNTIF(Data!$B$2:$B$2201,"<"&B21) -> 0 | E21: =COUNTIF(Data!$B$2:$B$2201,">"&C21) -> 0 | F21: =IF(D21+E21=0,"OK","CHECK") -> OK
A22: soil_moisture (%) | B22: =Assumptions!B17 -> 0 | C22: =Assumptions!B18 -> 100 | D22: =COUNTIF(Data!$C$2:$C$2201,"<"&B22) -> 0 | E22: =COUNTIF(Data!$C$2:$C$2201,">"&C22) -> 0 | F22: =IF(D22+E22=0,"OK","CHECK") -> OK
A24: 4. Category labels & rule consistency
A25: Check | B25: Rows affected | C25: Status
A26: Temperature Category: labels other than Cool/Moderate/Hot | B26: =ROWS(Data!$A$2:$A$2201)-(COUNTIF(Data!$D$2:$D$2201,"Cool")+COUNTIF(Data!$D$2:$D$2201,"Moderate")+COUNTIF(Data!$D$2:$D$2201,"Hot")) -> 0 | C26: =IF(B26=0,"OK","CHECK") -> OK
A27: Rainfall Category: labels other than Low/Moderate/High | B27: =ROWS(Data!$A$2:$A$2201)-(COUNTIF(Data!$E$2:$E$2201,"Low")+COUNTIF(Data!$E$2:$E$2201,"Moderate")+COUNTIF(Data!$E$2:$E$2201,"High")) -> 0 | C27: =IF(B27=0,"OK","CHECK") -> OK
A28: Water Requirement: labels other than Low/Medium/High | B28: =ROWS(Data!$A$2:$A$2201)-(COUNTIF(Data!$F$2:$F$2201,"Low")+COUNTIF(Data!$F$2:$F$2201,"Medium")+COUNTIF(Data!$F$2:$F$2201,"High")) -> 0 | C28: =IF(B28=0,"OK","CHECK") -> OK
A29: Irrigation Status: labels other than the 3 expected | B29: =ROWS(Data!$A$2:$A$2201)-(COUNTIF(Data!$G$2:$G$2201,"Irrigate Now")+COUNTIF(Data!$G$2:$G$2201,"Monitor")+COUNTIF(Data!$G$2:$G$2201,"No Irrigation Needed")) -> 0 | C29: =IF(B29=0,"OK","CHECK") -> OK
A30: Text cells with leading/trailing spaces (5 text columns) | B30: =SUMPRODUCT(--(LEN(Data!$D$2:$H$2201)<>LEN(TRIM(Data!$D$2:$H$2201)))) -> 0 | C30: =IF(B30=0,"OK","CHECK") -> OK
A31: Temperature Category disagrees with temperature cutoffs | B31: =COUNTIFS(Data!$D$2:$D$2201,"Cool",Data!$A$2:$A$2201,">="&Assumptions!$B$5)+COUNTIFS(Data!$D$2:$D$2201,"Moderate",Data!$A$2:$A$2201,"<"&Assumptions!$B$5)+COUNTIFS(Data!$D$2:$D$2201,"Moderate",Data!$A$2:$A$2201,">="&Assumptions!$B$6)+COUNTIFS(Data!$D$2:$D$2201,"Hot",Data!$A$2:$A$2201,"<"&Assumptions!$B$6) -> 0 | C31: =IF(B31=0,"OK","CHECK") -> OK
A32: Rainfall Category disagrees with rainfall cutoffs | B32: =COUNTIFS(Data!$E$2:$E$2201,"Low",Data!$B$2:$B$2201,">="&Assumptions!$B$7)+COUNTIFS(Data!$E$2:$E$2201,"Moderate",Data!$B$2:$B$2201,"<"&Assumptions!$B$7)+COUNTIFS(Data!$E$2:$E$2201,"Moderate",Data!$B$2:$B$2201,">="&Assumptions!$B$8)+COUNTIFS(Data!$E$2:$E$2201,"High",Data!$B$2:$B$2201,"<"&Assumptions!$B$8) -> 0 | C32: =IF(B32=0,"OK","CHECK") -> OK
A33: Irrigation Status disagrees with the moisture + rainfall rule | B33: =COUNTIF(Data!$O$2:$O$2201,0) -> 0 | C33: =IF(B33=0,"OK","CHECK") -> OK
A35: Overall verdict | B35: =IF(AND(COUNTIF(F5:F12,"CHECK")=0,C16="OK",COUNTIF(F20:F22,"CHECK")=0,COUNTIF(C26:C33,"CHECK")=0),"PASS - no missing, duplicate, out-of-range or inconsistent entries found","REVIEW - see CHECK items above") -> PASS - no missing, duplicate, out-of-range or inconsistent entries found
A37: Note: soil moisture values have many decimals (e.g. 29.446...), which suggests generated rather than sensor-logged values. Not an error, but worth stating in the report.

Sheet Frequency
A1: Grouped Frequency Distributions
A2: Class = lower limit <= x < upper limit. Blue cells (start, width) can be changed; the table rebuilds. Sturges rule for n=2,200 suggests about 12 classes.
A4: Temperature (°C) | K4: Temperature Category
A5: Start (lower limit) | B5: 8 | C5: Class width | D5: 3 | K5: Category | L5: Count | M5: %
A6: Class | B6: Lower | C6: Upper | D6: Midpoint | E6: Frequency | F6: Relative freq | G6: Cumulative freq | H6: Cumulative % | K6: Cool | L6: =COUNTIF(Data!$D$2:$D$2201,K6) -> 291 | M6: =L6/ROWS(Data!$A$2:$A$2201) -> 0.13227273
A7: =TEXT(B7,"0.0")&" - "&TEXT(C7,"0.0") -> 8.0 - 11.0 | B7: =$B$5 -> 8 | C7: =B7+$D$5 -> 11 | D7: =(B7+C7)/2 -> 9.5 | E7: =COUNTIFS(Data!$A$2:$A$2201,">="&B7,Data!$A$2:$A$2201,"<"&C7) -> 14 | F7: =E7/$E$19 -> 0.0063636364 | G7: =SUM($E$7:E7) -> 14 | H7: =G7/$E$19 -> 0.0063636364 | K7: Moderate | L7: =COUNTIF(Data!$D$2:$D$2201,K7) -> 1611 | M7: =L7/ROWS(Data!$A$2:$A$2201) -> 0.73227273
A8: =TEXT(B8,"0.0")&" - "&TEXT(C8,"0.0") -> 11.0 - 14.0 | B8: =C7 -> 11 | C8: =B8+$D$5 -> 14 | D8: =(B8+C8)/2 -> 12.5 | E8: =COUNTIFS(Data!$A$2:$A$2201,">="&B8,Data!$A$2:$A$2201,"<"&C8) -> 24 | F8: =E8/$E$19 -> 0.010909091 | G8: =SUM($E$7:E8) -> 38 | H8: =G8/$E$19 -> 0.017272727 | K8: Hot | L8: =COUNTIF(Data!$D$2:$D$2201,K8) -> 298 | M8: =L8/ROWS(Data!$A$2:$A$2201) -> 0.13545455
A9: =TEXT(B9,"0.0")&" - "&TEXT(C9,"0.0") -> 14.0 - 17.0 | B9: =C8 -> 14 | C9: =B9+$D$5 -> 17 | D9: =(B9+C9)/2 -> 15.5 | E9: =COUNTIFS(Data!$A$2:$A$2201,">="&B9,Data!$A$2:$A$2201,"<"&C9) -> 29 | F9: =E9/$E$19 -> 0.013181818 | G9: =SUM($E$7:E9) -> 67 | H9: =G9/$E$19 -> 0.030454545
A10: =TEXT(B10,"0.0")&" - "&TEXT(C10,"0.0") -> 17.0 - 20.0 | B10: =C9 -> 17 | C10: =B10+$D$5 -> 20 | D10: =(B10+C10)/2 -> 18.5 | E10: =COUNTIFS(Data!$A$2:$A$2201,">="&B10,Data!$A$2:$A$2201,"<"&C10) -> 224 | F10: =E10/$E$19 -> 0.10181818 | G10: =SUM($E$7:E10) -> 291 | H10: =G10/$E$19 -> 0.13227273
A11: =TEXT(B11,"0.0")&" - "&TEXT(C11,"0.0") -> 20.0 - 23.0 | B11: =C10 -> 20 | C11: =B11+$D$5 -> 23 | D11: =(B11+C11)/2 -> 21.5 | E11: =COUNTIFS(Data!$A$2:$A$2201,">="&B11,Data!$A$2:$A$2201,"<"&C11) -> 292 | F11: =E11/$E$19 -> 0.13272727 | G11: =SUM($E$7:E11) -> 583 | H11: =G11/$E$19 -> 0.265 | K11: Rainfall Category
A12: =TEXT(B12,"0.0")&" - "&TEXT(C12,"0.0") -> 23.0 - 26.0 | B12: =C11 -> 23 | C12: =B12+$D$5 -> 26 | D12: =(B12+C12)/2 -> 24.5 | E12: =COUNTIFS(Data!$A$2:$A$2201,">="&B12,Data!$A$2:$A$2201,"<"&C12) -> 600 | F12: =E12/$E$19 -> 0.27272727 | G12: =SUM($E$7:E12) -> 1183 | H12: =G12/$E$19 -> 0.53772727 | K12: Category | L12: Count | M12: %
A13: =TEXT(B13,"0.0")&" - "&TEXT(C13,"0.0") -> 26.0 - 29.0 | B13: =C12 -> 26 | C13: =B13+$D$5 -> 29 | D13: =(B13+C13)/2 -> 27.5 | E13: =COUNTIFS(Data!$A$2:$A$2201,">="&B13,Data!$A$2:$A$2201,"<"&C13) -> 548 | F13: =E13/$E$19 -> 0.24909091 | G13: =SUM($E$7:E13) -> 1731 | H13: =G13/$E$19 -> 0.78681818 | K13: Low | L13: =COUNTIF(Data!$E$2:$E$2201,K13) -> 331 | M13: =L13/ROWS(Data!$A$2:$A$2201) -> 0.15045455
A14: =TEXT(B14,"0.0")&" - "&TEXT(C14,"0.0") -> 29.0 - 32.0 | B14: =C13 -> 29 | C14: =B14+$D$5 -> 32 | D14: =(B14+C14)/2 -> 30.5 | E14: =COUNTIFS(Data!$A$2:$A$2201,">="&B14,Data!$A$2:$A$2201,"<"&C14) -> 288 | F14: =E14/$E$19 -> 0.13090909 | G14: =SUM($E$7:E14) -> 2019 | H14: =G14/$E$19 -> 0.91772727 | K14: Moderate | L14: =COUNTIF(Data!$E$2:$E$2201,K14) -> 1444 | M14: =L14/ROWS(Data!$A$2:$A$2201) -> 0.65636364
A15: =TEXT(B15,"0.0")&" - "&TEXT(C15,"0.0") -> 32.0 - 35.0 | B15: =C14 -> 32 | C15: =B15+$D$5 -> 35 | D15: =(B15+C15)/2 -> 33.5 | E15: =COUNTIFS(Data!$A$2:$A$2201,">="&B15,Data!$A$2:$A$2201,"<"&C15) -> 98 | F15: =E15/$E$19 -> 0.044545455 | G15: =SUM($E$7:E15) -> 2117 | H15: =G15/$E$19 -> 0.96227273 | K15: High | L15: =COUNTIF(Data!$E$2:$E$2201,K15) -> 425 | M15: =L15/ROWS(Data!$A$2:$A$2201) -> 0.19318182
A16: =TEXT(B16,"0.0")&" - "&TEXT(C16,"0.0") -> 35.0 - 38.0 | B16: =C15 -> 35 | C16: =B16+$D$5 -> 38 | D16: =(B16+C16)/2 -> 36.5 | E16: =COUNTIFS(Data!$A$2:$A$2201,">="&B16,Data!$A$2:$A$2201,"<"&C16) -> 38 | F16: =E16/$E$19 -> 0.017272727 | G16: =SUM($E$7:E16) -> 2155 | H16: =G16/$E$19 -> 0.97954545
A17: =TEXT(B17,"0.0")&" - "&TEXT(C17,"0.0") -> 38.0 - 41.0 | B17: =C16 -> 38 | C17: =B17+$D$5 -> 41 | D17: =(B17+C17)/2 -> 39.5 | E17: =COUNTIFS(Data!$A$2:$A$2201,">="&B17,Data!$A$2:$A$2201,"<"&C17) -> 23 | F17: =E17/$E$19 -> 0.010454545 | G17: =SUM($E$7:E17) -> 2178 | H17: =G17/$E$19 -> 0.99
A18: =TEXT(B18,"0.0")&" - "&TEXT(C18,"0.0") -> 41.0 - 44.0 | B18: =C17 -> 41 | C18: =B18+$D$5 -> 44 | D18: =(B18+C18)/2 -> 42.5 | E18: =COUNTIFS(Data!$A$2:$A$2201,">="&B18,Data!$A$2:$A$2201,"<"&C18) -> 22 | F18: =E18/$E$19 -> 0.01 | G18: =SUM($E$7:E18) -> 2200 | H18: =G18/$E$19 -> 1 | K18: Water Requirement
A19: Total | E19: =SUM(E7:E18) -> 2200 | F19: =SUM(F7:F18) -> 1 | G19: =IF(E19=ROWS(Data!$A$2:$A$2201),"OK: total = n","CHECK: values outside classes") -> OK: total = n | K19: Category | L19: Count | M19: %
K20: Low | L20: =COUNTIF(Data!$F$2:$F$2201,K20) -> 728 | M20: =L20/ROWS(Data!$A$2:$A$2201) -> 0.33090909
K21: Medium | L21: =COUNTIF(Data!$F$2:$F$2201,K21) -> 747 | M21: =L21/ROWS(Data!$A$2:$A$2201) -> 0.33954545
A22: Rainfall (mm) | K22: High | L22: =COUNTIF(Data!$F$2:$F$2201,K22) -> 725 | M22: =L22/ROWS(Data!$A$2:$A$2201) -> 0.32954545
A23: Start (lower limit) | B23: 0 | C23: Class width | D23: 25
A24: Class | B24: Lower | C24: Upper | D24: Midpoint | E24: Frequency | F24: Relative freq | G24: Cumulative freq | H24: Cumulative %
A25: =TEXT(B25,"0.0")&" - "&TEXT(C25,"0.0") -> 0.0 - 25.0 | B25: =$B$23 -> 0 | C25: =B25+$D$23 -> 25 | D25: =(B25+C25)/2 -> 12.5 | E25: =COUNTIFS(Data!$B$2:$B$2201,">="&B25,Data!$B$2:$B$2201,"<"&C25) -> 53 | F25: =E25/$E$37 -> 0.024090909 | G25: =SUM($E$25:E25) -> 53 | H25: =G25/$E$37 -> 0.024090909 | K25: Irrigation Status
A26: =TEXT(B26,"0.0")&" - "&TEXT(C26,"0.0") -> 25.0 - 50.0 | B26: =C25 -> 25 | C26: =B26+$D$23 -> 50 | D26: =(B26+C26)/2 -> 37.5 | E26: =COUNTIFS(Data!$B$2:$B$2201,">="&B26,Data!$B$2:$B$2201,"<"&C26) -> 278 | F26: =E26/$E$37 -> 0.12636364 | G26: =SUM($E$25:E26) -> 331 | H26: =G26/$E$37 -> 0.15045455 | K26: Category | L26: Count | M26: %
A27: =TEXT(B27,"0.0")&" - "&TEXT(C27,"0.0") -> 50.0 - 75.0 | B27: =C26 -> 50 | C27: =B27+$D$23 -> 75 | D27: =(B27+C27)/2 -> 62.5 | E27: =COUNTIFS(Data!$B$2:$B$2201,">="&B27,Data!$B$2:$B$2201,"<"&C27) -> 503 | F27: =E27/$E$37 -> 0.22863636 | G27: =SUM($E$25:E27) -> 834 | H27: =G27/$E$37 -> 0.37909091 | K27: Irrigate Now | L27: =COUNTIF(Data!$G$2:$G$2201,K27) -> 456 | M27: =L27/ROWS(Data!$A$2:$A$2201) -> 0.20727273
A28: =TEXT(B28,"0.0")&" - "&TEXT(C28,"0.0") -> 75.0 - 100.0 | B28: =C27 -> 75 | C28: =B28+$D$23 -> 100 | D28: =(B28+C28)/2 -> 87.5 | E28: =COUNTIFS(Data!$B$2:$B$2201,">="&B28,Data!$B$2:$B$2201,"<"&C28) -> 353 | F28: =E28/$E$37 -> 0.16045455 | G28: =SUM($E$25:E28) -> 1187 | H28: =G28/$E$37 -> 0.53954545 | K28: Monitor | L28: =COUNTIF(Data!$G$2:$G$2201,K28) -> 1480 | M28: =L28/ROWS(Data!$A$2:$A$2201) -> 0.67272727
A29: =TEXT(B29,"0.0")&" - "&TEXT(C29,"0.0") -> 100.0 - 125.0 | B29: =C28 -> 100 | C29: =B29+$D$23 -> 125 | D29: =(B29+C29)/2 -> 112.5 | E29: =COUNTIFS(Data!$B$2:$B$2201,">="&B29,Data!$B$2:$B$2201,"<"&C29) -> 469 | F29: =E29/$E$37 -> 0.21318182 | G29: =SUM($E$25:E29) -> 1656 | H29: =G29/$E$37 -> 0.75272727 | K29: No Irrigation Needed | L29: =COUNTIF(Data!$G$2:$G$2201,K29) -> 264 | M29: =L29/ROWS(Data!$A$2:$A$2201) -> 0.12
A30: =TEXT(B30,"0.0")&" - "&TEXT(C30,"0.0") -> 125.0 - 150.0 | B30: =C29 -> 125 | C30: =B30+$D$23 -> 150 | D30: =(B30+C30)/2 -> 137.5 | E30: =COUNTIFS(Data!$B$2:$B$2201,">="&B30,Data!$B$2:$B$2201,"<"&C30) -> 119 | F30: =E30/$E$37 -> 0.054090909 | G30: =SUM($E$25:E30) -> 1775 | H30: =G30/$E$37 -> 0.80681818
A31: =TEXT(B31,"0.0")&" - "&TEXT(C31,"0.0") -> 150.0 - 175.0 | B31: =C30 -> 150 | C31: =B31+$D$23 -> 175 | D31: =(B31+C31)/2 -> 162.5 | E31: =COUNTIFS(Data!$B$2:$B$2201,">="&B31,Data!$B$2:$B$2201,"<"&C31) -> 127 | F31: =E31/$E$37 -> 0.057727273 | G31: =SUM($E$25:E31) -> 1902 | H31: =G31/$E$37 -> 0.86454545
A32: =TEXT(B32,"0.0")&" - "&TEXT(C32,"0.0") -> 175.0 - 200.0 | B32: =C31 -> 175 | C32: =B32+$D$23 -> 200 | D32: =(B32+C32)/2 -> 187.5 | E32: =COUNTIFS(Data!$B$2:$B$2201,">="&B32,Data!$B$2:$B$2201,"<"&C32) -> 166 | F32: =E32/$E$37 -> 0.075454545 | G32: =SUM($E$25:E32) -> 2068 | H32: =G32/$E$37 -> 0.94
A33: =TEXT(B33,"0.0")&" - "&TEXT(C33,"0.0") -> 200.0 - 225.0 | B33: =C32 -> 200 | C33: =B33+$D$23 -> 225 | D33: =(B33+C33)/2 -> 212.5 | E33: =COUNTIFS(Data!$B$2:$B$2201,">="&B33,Data!$B$2:$B$2201,"<"&C33) -> 59 | F33: =E33/$E$37 -> 0.026818182 | G33: =SUM($E$25:E33) -> 2127 | H33: =G33/$E$37 -> 0.96681818
A34: =TEXT(B34,"0.0")&" - "&TEXT(C34,"0.0") -> 225.0 - 250.0 | B34: =C33 -> 225 | C34: =B34+$D$23 -> 250 | D34: =(B34+C34)/2 -> 237.5 | E34: =COUNTIFS(Data!$B$2:$B$2201,">="&B34,Data!$B$2:$B$2201,"<"&C34) -> 35 | F34: =E34/$E$37 -> 0.015909091 | G34: =SUM($E$25:E34) -> 2162 | H34: =G34/$E$37 -> 0.98272727
A35: =TEXT(B35,"0.0")&" - "&TEXT(C35,"0.0") -> 250.0 - 275.0 | B35: =C34 -> 250 | C35: =B35+$D$23 -> 275 | D35: =(B35+C35)/2 -> 262.5 | E35: =COUNTIFS(Data!$B$2:$B$2201,">="&B35,Data!$B$2:$B$2201,"<"&C35) -> 22 | F35: =E35/$E$37 -> 0.01 | G35: =SUM($E$25:E35) -> 2184 | H35: =G35/$E$37 -> 0.99272727
A36: =TEXT(B36,"0.0")&" - "&TEXT(C36,"0.0") -> 275.0 - 300.0 | B36: =C35 -> 275 | C36: =B36+$D$23 -> 300 | D36: =(B36+C36)/2 -> 287.5 | E36: =COUNTIFS(Data!$B$2:$B$2201,">="&B36,Data!$B$2:$B$2201,"<"&C36) -> 16 | F36: =E36/$E$37 -> 0.0072727273 | G36: =SUM($E$25:E36) -> 2200 | H36: =G36/$E$37 -> 1
A37: Total | E37: =SUM(E25:E36) -> 2200 | F37: =SUM(F25:F36) -> 1 | G37: =IF(E37=ROWS(Data!$B$2:$B$2201),"OK: total = n","CHECK: values outside classes") -> OK: total = n
A40: Soil moisture (%)
A41: Start (lower limit) | B41: 10 | C41: Class width | D41: 2
A42: Class | B42: Lower | C42: Upper | D42: Midpoint | E42: Frequency | F42: Relative freq | G42: Cumulative freq | H42: Cumulative %
A43: =TEXT(B43,"0.0")&" - "&TEXT(C43,"0.0") -> 10.0 - 12.0 | B43: =$B$41 -> 10 | C43: =B43+$D$41 -> 12 | D43: =(B43+C43)/2 -> 11 | E43: =COUNTIFS(Data!$C$2:$C$2201,">="&B43,Data!$C$2:$C$2201,"<"&C43) -> 214 | F43: =E43/$E$53 -> 0.097272727 | G43: =SUM($E$43:E43) -> 214 | H43: =G43/$E$53 -> 0.097272727
...

Sheet Descriptive
A1: Descriptive Statistics
A2: All values are live Excel formulas on the Data sheet. n = 2,200 records.
A4: Statistic | B4: Temperature (°C) | C4: Rainfall (mm) | D4: Soil moisture (%) | E4: How to read it
A5: Count | B5: =COUNT(Data!$A$2:$A$2201) -> 2200 | C5: =COUNT(Data!$B$2:$B$2201) -> 2200 | D5: =COUNT(Data!$C$2:$C$2201) -> 2200 | E5: Number of valid readings.
A6: Mean | B6: =AVERAGE(Data!$A$2:$A$2201) -> 25.616244 | C6: =AVERAGE(Data!$B$2:$B$2201) -> 103.46366 | D6: =AVERAGE(Data!$C$2:$C$2201) -> 20.151388 | E6: Arithmetic average.
A7: Median | B7: =MEDIAN(Data!$A$2:$A$2201) -> 25.598693 | C7: =MEDIAN(Data!$B$2:$B$2201) -> 94.867624 | D7: =MEDIAN(Data!$C$2:$C$2201) -> 20.088481 | E7: Middle value; robust to extreme values. Compare with the mean to spot skew.
A8: Mode (raw values) | B8: =IFERROR(MODE(Data!$A$2:$A$2201),"No repeated value") -> No repeated value | C8: =IFERROR(MODE(Data!$B$2:$B$2201),"No repeated value") -> No repeated value | D8: =IFERROR(MODE(Data!$C$2:$C$2201),"No repeated value") -> No repeated value | E8: Readings are continuous decimals, so no value repeats. Use the modal class below.
A9: Modal class (grouped) | B9: =INDEX(Frequency!$A$7:$A$18,MATCH(MAX(Frequency!$E$7:$E$18),Frequency!$E$7:$E$18,0)) -> 23.0 - 26.0 | C9: =INDEX(Frequency!$A$25:$A$36,MATCH(MAX(Frequency!$E$25:$E$36),Frequency!$E$25:$E$36,0)) -> 50.0 - 75.0 | D9: =INDEX(Frequency!$A$43:$A$52,MATCH(MAX(Frequency!$E$43:$E$52),Frequency!$E$43:$E$52,0)) -> 28.0 - 30.0 | E9: Most frequent class from the Frequency sheet (first one if tied).
A10: Variance (sample) | B10: =VAR(Data!$A$2:$A$2201) -> 25.64155 | C10: =VAR(Data!$B$2:$B$2201) -> 3020.4245 | D10: =VAR(Data!$C$2:$C$2201) -> 33.567189 | E10: Average squared distance from the mean, n-1 divisor.
A11: Variance (population) | B11: =VARP(Data!$A$2:$A$2201) -> 25.629895 | C11: =VARP(Data!$B$2:$B$2201) -> 3019.0515 | D11: =VARP(Data!$C$2:$C$2201) -> 33.551932 | E11: n divisor. Almost identical here because n is large.
A12: Std deviation (sample) | B12: =STDEV(Data!$A$2:$A$2201) -> 5.0637486 | C12: =STDEV(Data!$B$2:$B$2201) -> 54.958389 | D12: =STDEV(Data!$C$2:$C$2201) -> 5.7937198 | E12: Typical spread around the mean, in the original units.
A13: Std deviation (population) | B13: =STDEVP(Data!$A$2:$A$2201) -> 5.0625976 | C13: =STDEVP(Data!$B$2:$B$2201) -> 54.945897 | D13: =STDEVP(Data!$C$2:$C$2201) -> 5.7924029 | E13: n divisor.
A14: Minimum | B14: =MIN(Data!$A$2:$A$2201) -> 8.8256747 | C14: =MIN(Data!$B$2:$B$2201) -> 20.211267 | D14: =MIN(Data!$C$2:$C$2201) -> 10.02426
A15: Maximum | B15: =MAX(Data!$A$2:$A$2201) -> 43.675493 | C15: =MAX(Data!$B$2:$B$2201) -> 298.56012 | D15: =MAX(Data!$C$2:$C$2201) -> 29.99786
A16: Range | B16: =MAX(Data!$A$2:$A$2201)-MIN(Data!$A$2:$A$2201) -> 34.849818 | C16: =MAX(Data!$B$2:$B$2201)-MIN(Data!$B$2:$B$2201) -> 278.34885 | D16: =MAX(Data!$C$2:$C$2201)-MIN(Data!$C$2:$C$2201) -> 19.973599 | E16: Max - Min.
A17: Q1 (25th percentile) | B17: =QUARTILE(Data!$A$2:$A$2201,1) -> 22.769375 | C17: =QUARTILE(Data!$B$2:$B$2201,1) -> 64.551686 | D17: =QUARTILE(Data!$C$2:$C$2201,1) -> 15.179949 | E17: 25% of readings fall below this.
A18: Q3 (75th percentile) | B18: =QUARTILE(Data!$A$2:$A$2201,3) -> 28.561654 | C18: =QUARTILE(Data!$B$2:$B$2201,3) -> 124.26751 | D18: =QUARTILE(Data!$C$2:$C$2201,3) -> 25.255146 | E18: 75% of readings fall below this.
A19: IQR (Q3 - Q1) | B19: =QUARTILE(Data!$A$2:$A$2201,3)-QUARTILE(Data!$A$2:$A$2201,1) -> 5.7922793 | C19: =QUARTILE(Data!$B$2:$B$2201,3)-QUARTILE(Data!$B$2:$B$2201,1) -> 59.715822 | D19: =QUARTILE(Data!$C$2:$C$2201,3)-QUARTILE(Data!$C$2:$C$2201,1) -> 10.075197 | E19: Spread of the middle 50%.
A20: Coefficient of variation | B20: =STDEV(Data!$A$2:$A$2201)/AVERAGE(Data!$A$2:$A$2201) -> 0.19767725 | C20: =STDEV(Data!$B$2:$B$2201)/AVERAGE(Data!$B$2:$B$2201) -> 0.53118545 | D20: =STDEV(Data!$C$2:$C$2201)/AVERAGE(Data!$C$2:$C$2201) -> 0.28750972 | E20: SD relative to the mean; lets you compare spread across variables.
A21: Skewness | B21: =SKEW(Data!$A$2:$A$2201) -> 0.18493273 | C21: =SKEW(Data!$B$2:$B$2201) -> 0.96575635 | D21: =SKEW(Data!$C$2:$C$2201) -> -0.01763795 | E21: About 0 = symmetric; > 0.5 = long right tail; < -0.5 = long left tail.
A22: Kurtosis (excess) | B22: =KURT(Data!$A$2:$A$2201) -> 1.2325549 | C22: =KURT(Data!$B$2:$B$2201) -> 0.60707929 | D22: =KURT(Data!$C$2:$C$2201) -> -1.2153023 | E22: 0 = normal-like tails; negative = flatter than normal.
A23: Standard error of mean | B23: =STDEV(Data!$A$2:$A$2201)/SQRT(COUNT(Data!$A$2:$A$2201)) -> 0.10795948 | C23: =STDEV(Data!$B$2:$B$2201)/SQRT(COUNT(Data!$B$2:$B$2201)) -> 1.1717168 | D23: =STDEV(Data!$C$2:$C$2201)/SQRT(COUNT(Data!$C$2:$C$2201)) -> 0.12352252 | E23: Uncertainty of the mean as an estimate.
A24: 95% CI for mean - lower | B24: =B6-TINV(0.05,B5-1)*B23 -> 25.404531 | C24: =C6-TINV(0.05,C5-1)*C23 -> 101.16587 | D24: =D6-TINV(0.05,D5-1)*D23 -> 19.909155 | E24: Mean - t x SE (t from TINV, 0.05, n-1).
A25: 95% CI for mean - upper | B25: =B6+TINV(0.05,B5-1)*B23 -> 25.827957 | C25: =C6+TINV(0.05,C5-1)*C23 -> 105.76144 | D25: =D6+TINV(0.05,D5-1)*D23 -> 20.393621 | E25: Mean + t x SE.
A27: Interpretation
A28: Soil moisture averages 20.15% (median 20.09%, SD 5.79) and spans almost exactly 10-30% with skewness near 0 (-0.02) and negative kurtosis (-1.22): readings are spread evenly across the range instead of clustering around a typical value.
A29: Temperature is roughly symmetric (mean 25.62 °C, median 25.60 °C, SD 5.06, skew 0.18). Rainfall is right-skewed (mean 103.5 mm > median 94.9 mm, skew 0.97): a minority of very wet records pull the mean up, so the median describes typical rainfall better.
A30: Text above reflects the data at build time; re-read it if the Data sheet changes.

Sheet Correlation
A1: Correlation Analysis
A2: Pearson r computed with CORREL on all 2,200 records.
A3: Correlation matrix
B4: Temperature | C4: Rainfall | D4: Soil moisture
A5: Temperature | B5: =CORREL(Data!$A$2:$A$2201,Data!$A$2:$A$2201) -> 1 | C5: =CORREL(Data!$A$2:$A$2201,Data!$B$2:$B$2201) -> -0.030083781 | D5: =CORREL(Data!$A$2:$A$2201,Data!$C$2:$C$2201) -> -0.009842308
A6: Rainfall | B6: =CORREL(Data!$B$2:$B$2201,Data!$A$2:$A$2201) -> -0.030083781 | C6: =CORREL(Data!$B$2:$B$2201,Data!$B$2:$B$2201) -> 1 | D6: =CORREL(Data!$B$2:$B$2201,Data!$C$2:$C$2201) -> -0.048593299
A7: Soil moisture | B7: =CORREL(Data!$C$2:$C$2201,Data!$A$2:$A$2201) -> -0.009842308 | C7: =CORREL(Data!$C$2:$C$2201,Data!$B$2:$B$2201) -> -0.048593299 | D7: =CORREL(Data!$C$2:$C$2201,Data!$C$2:$C$2201) -> 1
A9: Pairwise detail
A10: Pair | B10: r | C10: r squared | D10: n | E10: t statistic | F10: p-value (2-tailed) | G10: Strength | H10: Direction
A11: Temperature vs Rainfall | B11: =B6 -> -0.030083781 | C11: =B11^2 -> 0.00090503387 | D11: =ROWS(Data!$A$2:$A$2201) -> 2200 | E11: =B11*SQRT((D11-2)/(1-B11^2)) -> -1.4110515 | F11: =TDIST(ABS(E11),D11-2,2) -> 0.15837094 | G11: =IF(ABS(B11)<0.1,"Negligible",IF(ABS(B11)<0.3,"Weak",IF(ABS(B11)<0.5,"Moderate",IF(ABS(B11)<0.7,"Strong","Very strong")))) -> Negligible | H11: =IF(B11>0,"Positive","Negative") -> Negative
A12: Temperature vs Soil moisture | B12: =B7 -> -0.009842308 | C12: =B12^2 -> 9.6871027e-05 | D12: =ROWS(Data!$A$2:$A$2201) -> 2200 | E12: =B12*SQRT((D12-2)/(1-B12^2)) -> -0.46145763 | F12: =TDIST(ABS(E12),D12-2,2) -> 0.64451597 | G12: =IF(ABS(B12)<0.1,"Negligible",IF(ABS(B12)<0.3,"Weak",IF(ABS(B12)<0.5,"Moderate",IF(ABS(B12)<0.7,"Strong","Very strong")))) -> Negligible | H12: =IF(B12>0,"Positive","Negative") -> Negative
A13: Rainfall vs Soil moisture | B13: =C7 -> -0.048593299 | C13: =B13^2 -> 0.0023613087 | D13: =ROWS(Data!$A$2:$A$2201) -> 2200 | E13: =B13*SQRT((D13-2)/(1-B13^2)) -> -2.280886 | F13: =TDIST(ABS(E13),D13-2,2) -> 0.022650491 | G13: =IF(ABS(B13)<0.1,"Negligible",IF(ABS(B13)<0.3,"Weak",IF(ABS(B13)<0.5,"Moderate",IF(ABS(B13)<0.7,"Strong","Very strong")))) -> Negligible | H13: =IF(B13>0,"Positive","Negative") -> Negative
A15: Strength labels: |r| < 0.1 negligible, < 0.3 weak, < 0.5 moderate, < 0.7 strong, otherwise very strong (common rule of thumb; stated here as an assumption).
A17: Interpretation
A18: All three correlations are negligible (|r| < 0.05). Rainfall vs soil moisture is r = -0.049 (p = 0.023): with 2,200 records even a tiny r can be "statistically significant", but r squared is only about 0.24%, so it explains almost nothing.
A19: In real fields, rainfall normally raises soil moisture (a clear positive r). Its absence here suggests soil moisture was not generated from rainfall, which fits a simulated or randomly assigned variable. State this as a limitation in the report.
A20: Correlation describes association only; it does not show that one variable causes another.

Sheet CrossTab
A1: Cross-Tabulation: category vs irrigation status
A2: Counts, row %, column %, and a chi-square test of independence (valid here because every expected count is large).
A4: A. Rainfall Category x Irrigation Status
A5: Counts
A6: Rainfall Category | B6: Irrigate Now | C6: Monitor | D6: No Irrigation Needed | E6: Total
A7: Low | B7: =COUNTIFS(Data!$E$2:$E$2201,$A7,Data!$G$2:$G$2201,B$6) -> 128 | C7: =COUNTIFS(Data!$E$2:$E$2201,$A7,Data!$G$2:$G$2201,C$6) -> 203 | D7: =COUNTIFS(Data!$E$2:$E$2201,$A7,Data!$G$2:$G$2201,D$6) -> 0 | E7: =SUM(B7:D7) -> 331
A8: Moderate | B8: =COUNTIFS(Data!$E$2:$E$2201,$A8,Data!$G$2:$G$2201,B$6) -> 328 | C8: =COUNTIFS(Data!$E$2:$E$2201,$A8,Data!$G$2:$G$2201,C$6) -> 947 | D8: =COUNTIFS(Data!$E$2:$E$2201,$A8,Data!$G$2:$G$2201,D$6) -> 169 | E8: =SUM(B8:D8) -> 1444
A9: High | B9: =COUNTIFS(Data!$E$2:$E$2201,$A9,Data!$G$2:$G$2201,B$6) -> 0 | C9: =COUNTIFS(Data!$E$2:$E$2201,$A9,Data!$G$2:$G$2201,C$6) -> 330 | D9: =COUNTIFS(Data!$E$2:$E$2201,$A9,Data!$G$2:$G$2201,D$6) -> 95 | E9: =SUM(B9:D9) -> 425
A10: Total | B10: =SUM(B7:B9) -> 456 | C10: =SUM(C7:C9) -> 1480 | D10: =SUM(D7:D9) -> 264 | E10: =SUM(E7:E9) -> 2200
A12: Row % (share of each category that gets each status)
A13: Rainfall Category | B13: Irrigate Now | C13: Monitor | D13: No Irrigation Needed | E13: Total
A14: Low | B14: =B7/$E7 -> 0.38670695 | C14: =C7/$E7 -> 0.61329305 | D14: =D7/$E7 -> 0 | E14: =SUM(B14:D14) -> 1
A15: Moderate | B15: =B8/$E8 -> 0.22714681 | C15: =C8/$E8 -> 0.65581717 | D15: =D8/$E8 -> 0.11703601 | E15: =SUM(B15:D15) -> 1
A16: High | B16: =B9/$E9 -> 0 | C16: =C9/$E9 -> 0.77647059 | D16: =D9/$E9 -> 0.22352941 | E16: =SUM(B16:D16) -> 1
A18: Column % (makeup of each status)
A19: Rainfall Category | B19: Irrigate Now | C19: Monitor | D19: No Irrigation Needed | E19: Total
A20: Low | B20: =B7/B$10 -> 0.28070175 | C20: =C7/C$10 -> 0.13716216 | D20: =D7/D$10 -> 0 | E20: =E7/$E$10 -> 0.15045455
A21: Moderate | B21: =B8/B$10 -> 0.71929825 | C21: =C8/C$10 -> 0.63986486 | D21: =D8/D$10 -> 0.64015152 | E21: =E8/$E$10 -> 0.65636364
A22: High | B22: =B9/B$10 -> 0 | C22: =C9/C$10 -> 0.22297297 | D22: =D9/D$10 -> 0.35984848 | E22: =E9/$E$10 -> 0.19318182
A24: Expected counts if category and status were independent
A25: Rainfall Category | B25: Irrigate Now | C25: Monitor | D25: No Irrigation Needed
A26: Low | B26: =$E7*B$10/$E$10 -> 68.607273 | C26: =$E7*C$10/$E$10 -> 222.67273 | D26: =$E7*D$10/$E$10 -> 39.72
A27: Moderate | B27: =$E8*B$10/$E$10 -> 299.30182 | C27: =$E8*C$10/$E$10 -> 971.41818 | D27: =$E8*D$10/$E$10 -> 173.28
A28: High | B28: =$E9*B$10/$E$10 -> 88.090909 | C28: =$E9*C$10/$E$10 -> 285.90909 | D28: =$E9*D$10/$E$10 -> 51
A30: Chi-square statistic | B30: =SUMPRODUCT((B7:D9-B26:D28)^2/B26:D28) -> 229.19611
A31: Degrees of freedom | B31: =(ROWS(B7:B9)-1)*(COLUMNS(B7:D7)-1) -> 4
A32: p-value | B32: =CHIDIST(B30,B31) -> 1.9662941e-48
A33: Cramer's V (effect size) | B33: =SQRT(B30/(E10*(MIN(ROWS(B7:D9),COLUMNS(B7:D9))-1))) -> 0.22823239 | C33: =IF(B33<0.1,"Negligible",IF(B33<0.3,"Weak",IF(B33<0.5,"Moderate","Strong"))) -> Weak
A35: Reading: 38.7% of Low-rainfall records are "Irrigate Now" and none are "No Irrigation Needed". High rainfall is the mirror image: 22.4% "No Irrigation Needed" and none "Irrigate Now". Moderate rainfall gives 22.7% / 11.7%. Chi-square = 229.2, p < 0.001, Cramer's V = 0.23.
A36: Caution: rainfall is one of the two inputs of the irrigation rule (Assumptions sheet), so this pattern is built in by design. It confirms the rule works, not that a new relationship was discovered.
A40: B. Temperature Category x Irrigation Status (extra)
A41: Counts
A42: Temperature Category | B42: Irrigate Now | C42: Monitor | D42: No Irrigation Needed | E42: Total
A43: Cool | B43: =COUNTIFS(Data!$D$2:$D$2201,$A43,Data!$G$2:$G$2201,B$42) -> 73 | C43: =COUNTIFS(Data!$D$2:$D$2201,$A43,Data!$G$2:$G$2201,C$42) -> 184 | D43: =COUNTIFS(Data!$D$2:$D$2201,$A43,Data!$G$2:$G$2201,D$42) -> 34 | E43: =SUM(B43:D43) -> 291
A44: Moderate | B44: =COUNTIFS(Data!$D$2:$D$2201,$A44,Data!$G$2:$G$2201,B$42) -> 300 | C44: =COUNTIFS(Data!$D$2:$D$2201,$A44,Data!$G$2:$G$2201,C$42) -> 1108 | D44: =COUNTIFS(Data!$D$2:$D$2201,$A44,Data!$G$2:$G$2201,D$42) -> 203 | E44: =SUM(B44:D44) -> 1611
A45: Hot | B45: =COUNTIFS(Data!$D$2:$D$2201,$A45,Data!$G$2:$G$2201,B$42) -> 83 | C45: =COUNTIFS(Data!$D$2:$D$2201,$A45,Data!$G$2:$G$2201,C$42) -> 188 | D45: =COUNTIFS(Data!$D$2:$D$2201,$A45,Data!$G$2:$G$2201,D$42) -> 27 | E45: =SUM(B45:D45) -> 298
A46: Total | B46: =SUM(B43:B45) -> 456 | C46: =SUM(C43:C45) -> 1480 | D46: =SUM(D43:D45) -> 264 | E46: =SUM(E43:E45) -> 2200
A48: Row % (share of each category that gets each status)
A49: Temperature Category | B49: Irrigate Now | C49: Monitor | D49: No Irrigation Needed | E49: Total
A50: Cool | B50: =B43/$E43 -> 0.25085911 | C50: =C43/$E43 -> 0.63230241 | D50: =D43/$E43 -> 0.11683849 | E50: =SUM(B50:D50) -> 1
...

Sheet Outliers
A1: Outlier Detection (IQR method)
A2: Outlier if value < Q1 - k x IQR or > Q3 + k x IQR. Flags per record are in Data columns I-K.
A3: IQR multiplier (k) | B3: 1.5 | C3: Standard Tukey fence value.
A5: Variable | B5: Q1 | C5: Q3 | D5: IQR | E5: Lower fence | F5: Upper fence | G5: # Low outliers | H5: # High outliers | I5: # Total | J5: % of records | K5: Data min | L5: Data max
A6: Temperature (°C) | B6: =QUARTILE(Data!$A$2:$A$2201,1) -> 22.769375 | C6: =QUARTILE(Data!$A$2:$A$2201,3) -> 28.561654 | D6: =C6-B6 -> 5.7922793 | E6: =B6-$B$3*D6 -> 14.080956 | F6: =C6+$B$3*D6 -> 37.250073 | G6: =COUNTIF(Data!$A$2:$A$2201,"<"&E6) -> 38 | H6: =COUNTIF(Data!$A$2:$A$2201,">"&F6) -> 48 | I6: =G6+H6 -> 86 | J6: =I6/ROWS(Data!$A$2:$A$2201) -> 0.039090909 | K6: =MIN(Data!$A$2:$A$2201) -> 8.8256747 | L6: =MAX(Data!$A$2:$A$2201) -> 43.675493
A7: Rainfall (mm) | B7: =QUARTILE(Data!$B$2:$B$2201,1) -> 64.551686 | C7: =QUARTILE(Data!$B$2:$B$2201,3) -> 124.26751 | D7: =C7-B7 -> 59.715822 | E7: =B7-$B$3*D7 -> -25.022047 | F7: =C7+$B$3*D7 -> 213.84124 | G7: =COUNTIF(Data!$B$2:$B$2201,"<"&E7) -> 0 | H7: =COUNTIF(Data!$B$2:$B$2201,">"&F7) -> 100 | I7: =G7+H7 -> 100 | J7: =I7/ROWS(Data!$B$2:$B$2201) -> 0.045454545 | K7: =MIN(Data!$B$2:$B$2201) -> 20.211267 | L7: =MAX(Data!$B$2:$B$2201) -> 298.56012
A8: Soil moisture (%) | B8: =QUARTILE(Data!$C$2:$C$2201,1) -> 15.179949 | C8: =QUARTILE(Data!$C$2:$C$2201,3) -> 25.255146 | D8: =C8-B8 -> 10.075197 | E8: =B8-$B$3*D8 -> 0.067153502 | F8: =C8+$B$3*D8 -> 40.367941 | G8: =COUNTIF(Data!$C$2:$C$2201,"<"&E8) -> 0 | H8: =COUNTIF(Data!$C$2:$C$2201,">"&F8) -> 0 | I8: =G8+H8 -> 0 | J8: =I8/ROWS(Data!$C$2:$C$2201) -> 0 | K8: =MIN(Data!$C$2:$C$2201) -> 10.02426 | L8: =MAX(Data!$C$2:$C$2201) -> 29.99786
A10: Interpretation
A11: Temperature has 86 outliers (38 cold, 48 hot). Rainfall has 100 high outliers and no low ones, consistent with its right skew (a few very heavy-rain records). Soil moisture has none: its fences (0.1% and 40.4%) lie outside the actual 10-30% range.
A12: Recommendation: keep these records. The values are physically plausible extremes (see Validation range checks), not entry errors; removing them would hide real heavy-rain and heat events. Filter Data columns I-K to inspect them.

Sheet Comparison
A1: Comparative Analysis by category
A2: Group averages with AVERAGEIFS; "Std diff" = (group mean - overall mean) / overall sample SD, so variables on different scales can be compared.
A4: A. By Irrigation Status
A5: Irrigation Status | B5: N | C5: % of rows | D5: Avg moisture (%) | E5: Avg rainfall (mm) | F5: Avg temperature (°C) | G5: Min moisture | H5: Max moisture | I5: Min rainfall | J5: Max rainfall | K5: Std diff: moisture | L5: Std diff: rainfall | M5: Std diff: temperature
A6: Irrigate Now | B6: =COUNTIF(Data!$G$2:$G$2201,A6) -> 456 | C6: =B6/ROWS(Data!$A$2:$A$2201) -> 0.20727273 | D6: =AVERAGEIFS(Data!$C$2:$C$2201,Data!$G$2:$G$2201,A6) -> 13.992105 | E6: =AVERAGEIFS(Data!$B$2:$B$2201,Data!$G$2:$G$2201,A6) -> 64.955039 | F6: =AVERAGEIFS(Data!$A$2:$A$2201,Data!$G$2:$G$2201,A6) -> 26.173713 | G6: =_xlfn.MINIFS(Data!$C$2:$C$2201,Data!$G$2:$G$2201,A6) -> 10.048511 | H6: =_xlfn.MAXIFS(Data!$C$2:$C$2201,Data!$G$2:$G$2201,A6) -> 17.992056 | I6: =_xlfn.MINIFS(Data!$B$2:$B$2201,Data!$G$2:$G$2201,A6) -> 20.390205 | J6: =_xlfn.MAXIFS(Data!$B$2:$B$2201,Data!$G$2:$G$2201,A6) -> 99.931008 | K6: =(D6-D$9)/Descriptive!$D$12 -> -1.0630965 | L6: =(E6-E$9)/Descriptive!$C$12 -> -0.70068678 | M6: =(F6-F$9)/Descriptive!$B$12 -> 0.11009014
A7: Monitor | B7: =COUNTIF(Data!$G$2:$G$2201,A7) -> 1480 | C7: =B7/ROWS(Data!$A$2:$A$2201) -> 0.67272727 | D7: =AVERAGEIFS(Data!$C$2:$C$2201,Data!$G$2:$G$2201,A7) -> 20.71886 | E7: =AVERAGEIFS(Data!$B$2:$B$2201,Data!$G$2:$G$2201,A7) -> 108.05329 | F7: =AVERAGEIFS(Data!$A$2:$A$2201,Data!$G$2:$G$2201,A7) -> 25.578115 | G7: =_xlfn.MINIFS(Data!$C$2:$C$2201,Data!$G$2:$G$2201,A7) -> 10.02426 | H7: =_xlfn.MAXIFS(Data!$C$2:$C$2201,Data!$G$2:$G$2201,A7) -> 29.994929 | I7: =_xlfn.MINIFS(Data!$B$2:$B$2201,Data!$G$2:$G$2201,A7) -> 20.211267 | J7: =_xlfn.MAXIFS(Data!$B$2:$B$2201,Data!$G$2:$G$2201,A7) -> 298.56012 | K7: =(D7-D$9)/Descriptive!$D$12 -> 0.09794611 | L7: =(E7-E$9)/Descriptive!$C$12 -> 0.083511106 | M7: =(F7-F$9)/Descriptive!$B$12 -> -0.0075297374
A8: No Irrigation Needed | B8: =COUNTIF(Data!$G$2:$G$2201,A8) -> 264 | C8: =B8/ROWS(Data!$A$2:$A$2201) -> 0.12 | D8: =AVERAGEIFS(Data!$C$2:$C$2201,Data!$G$2:$G$2201,A8) -> 27.608865 | E8: =AVERAGEIFS(Data!$B$2:$B$2201,Data!$G$2:$G$2201,A8) -> 144.24876 | F8: =AVERAGEIFS(Data!$A$2:$A$2201,Data!$G$2:$G$2201,A8) -> 24.867095 | G8: =_xlfn.MINIFS(Data!$C$2:$C$2201,Data!$G$2:$G$2201,A8) -> 25.00861 | H8: =_xlfn.MAXIFS(Data!$C$2:$C$2201,Data!$G$2:$G$2201,A8) -> 29.99786 | I8: =_xlfn.MINIFS(Data!$B$2:$B$2201,Data!$G$2:$G$2201,A8) -> 100.11734 | J8: =_xlfn.MAXIFS(Data!$B$2:$B$2201,Data!$G$2:$G$2201,A8) -> 295.92488 | K8: =(D8-D$9)/Descriptive!$D$12 -> 1.2871657 | L8: =(E8-E$9)/Descriptive!$C$12 -> 0.74210885 | M8: =(F8-F$9)/Descriptive!$B$12 -> -0.14794353
A9: All records | B9: =ROWS(Data!$A$2:$A$2201) -> 2200 | C9: =SUM(C6:C8) -> 1 | D9: =AVERAGE(Data!$C$2:$C$2201) -> 20.151388 | E9: =AVERAGE(Data!$B$2:$B$2201) -> 103.46366 | F9: =AVERAGE(Data!$A$2:$A$2201) -> 25.616244 | G9: =MIN(Data!$C$2:$C$2201) -> 10.02426 | H9: =MAX(Data!$C$2:$C$2201) -> 29.99786 | I9: =MIN(Data!$B$2:$B$2201) -> 20.211267 | J9: =MAX(Data!$B$2:$B$2201) -> 298.56012
A12: B. By Water Requirement (extra)
A13: Water Requirement | B13: N | C13: % of rows | D13: Avg moisture (%) | E13: Avg rainfall (mm) | F13: Avg temperature (°C) | G13: Min moisture | H13: Max moisture | I13: Min rainfall | J13: Max rainfall
A14: Low | B14: =COUNTIF(Data!$F$2:$F$2201,A14) -> 728 | C14: =B14/ROWS(Data!$A$2:$A$2201) -> 0.33090909 | D14: =AVERAGEIFS(Data!$C$2:$C$2201,Data!$F$2:$F$2201,A14) -> 26.350871 | E14: =AVERAGEIFS(Data!$B$2:$B$2201,Data!$F$2:$F$2201,A14) -> 121.27219 | F14: =AVERAGEIFS(Data!$A$2:$A$2201,Data!$F$2:$F$2201,A14) -> 25.401397 | G14: =_xlfn.MINIFS(Data!$C$2:$C$2201,Data!$F$2:$F$2201,A14) -> 15.696491 | H14: =_xlfn.MAXIFS(Data!$C$2:$C$2201,Data!$F$2:$F$2201,A14) -> 29.99786 | I14: =_xlfn.MINIFS(Data!$B$2:$B$2201,Data!$F$2:$F$2201,A14) -> 20.211267 | J14: =_xlfn.MAXIFS(Data!$B$2:$B$2201,Data!$F$2:$F$2201,A14) -> 298.56012
A15: Medium | B15: =COUNTIF(Data!$F$2:$F$2201,A15) -> 747 | C15: =B15/ROWS(Data!$A$2:$A$2201) -> 0.33954545 | D15: =AVERAGEIFS(Data!$C$2:$C$2201,Data!$F$2:$F$2201,A15) -> 20.158217 | E15: =AVERAGEIFS(Data!$B$2:$B$2201,Data!$F$2:$F$2201,A15) -> 104.31648 | F15: =AVERAGEIFS(Data!$A$2:$A$2201,Data!$F$2:$F$2201,A15) -> 25.714311 | G15: =_xlfn.MINIFS(Data!$C$2:$C$2201,Data!$F$2:$F$2201,A15) -> 10.219504 | H15: =_xlfn.MAXIFS(Data!$C$2:$C$2201,Data!$F$2:$F$2201,A15) -> 27.21168 | I15: =_xlfn.MINIFS(Data!$B$2:$B$2201,Data!$F$2:$F$2201,A15) -> 21.445329 | J15: =_xlfn.MAXIFS(Data!$B$2:$B$2201,Data!$F$2:$F$2201,A15) -> 287.57669
A16: High | B16: =COUNTIF(Data!$F$2:$F$2201,A16) -> 725 | C16: =B16/ROWS(Data!$A$2:$A$2201) -> 0.32954545 | D16: =AVERAGEIFS(Data!$C$2:$C$2201,Data!$F$2:$F$2201,A16) -> 13.919215 | E16: =AVERAGEIFS(Data!$B$2:$B$2201,Data!$F$2:$F$2201,A16) -> 84.702725 | F16: =AVERAGEIFS(Data!$A$2:$A$2201,Data!$F$2:$F$2201,A16) -> 25.730937 | G16: =_xlfn.MINIFS(Data!$C$2:$C$2201,Data!$F$2:$F$2201,A16) -> 10.02426 | H16: =_xlfn.MAXIFS(Data!$C$2:$C$2201,Data!$F$2:$F$2201,A16) -> 20.161626 | I16: =_xlfn.MINIFS(Data!$B$2:$B$2201,Data!$F$2:$F$2201,A16) -> 20.360011 | J16: =_xlfn.MAXIFS(Data!$B$2:$B$2201,Data!$F$2:$F$2201,A16) -> 218.91636
A17: All records | B17: =ROWS(Data!$A$2:$A$2201) -> 2200 | C17: =SUM(C14:C16) -> 1 | D17: =AVERAGE(Data!$C$2:$C$2201) -> 20.151388 | E17: =AVERAGE(Data!$B$2:$B$2201) -> 103.46366 | F17: =AVERAGE(Data!$A$2:$A$2201) -> 25.616244 | G17: =MIN(Data!$C$2:$C$2201) -> 10.02426 | H17: =MAX(Data!$C$2:$C$2201) -> 29.99786 | I17: =MIN(Data!$B$2:$B$2201) -> 20.211267 | J17: =MAX(Data!$B$2:$B$2201) -> 298.56012
A20: Interpretation
A21: Average soil moisture rises from 14.0% (Irrigate Now) to 20.7% (Monitor) to 27.6% (No Irrigation Needed); average rainfall rises from 65 to 108 to 144 mm.
A22: Gap between the two extreme groups in SD units: moisture 2.35, rainfall 1.44, temperature -0.26. Temperature differs by only about 1.3 °C between groups, far less than its own spread.
